Workbook

Sheet Export Summary
B3: This document was exported from Numbers. Each table was converted to an Excel worksheet. All other objects on each Numbers sheet were placed on separate worksheets. Please be aware that formula calculations may differ in Excel.
B7: Numbers Sheet Name | C7: Numbers Table Name | D7: Excel Worksheet Name
B9: RECOMMENDED PRICES
C10: Table 1 | D10: RECOMMENDED PRICES
B11: PnL 2026 Plan-Forecast
C12: Table 1 | D12: PnL 2026 Plan-Forecast
B13: FCF 2025-2026 Forecast
C14: Table 1 | D14: FCF 2025-2026 Forecast
B15: Private Boats 2026 Target
C16: Table 1 | D16: Private Boats 2026 Target
B17: Shared Boats 2026 Target
C18: Table 1 | D18: Shared Boats 2026 Target
B19: Premium Shared 2026 Target
C20: Table 1 | D20: Premium Shared 2026 Target
B21: Premium for Couples 2026 Target
C22: Table 1 | D22: Premium for Couples 2026 Target
B23: Standard Diving Tour 2026
C24: Table 1 | D24: Standard Diving Tour 2026
B25: Premium Diving Tour 2026
C26: Table 1 | D26: Premium Diving Tour 2026
B27: Fishing Tour 2026 Target
C28: Table 1 | D28: Fishing Tour 2026 Target
B29: Project Eldorado ROI in IDR
C30: Table 1 | D30: Project Eldorado ROI in IDR
B31: Project Eldorado ROI in USD
C32: Table 1 | D32: Project Eldorado ROI in USD
B33: Project Eldorado IRR 50-50
C34: Table 1 | D34: Project Eldorado IRR 50-50
B35: Project Eldorado IRR 80-20
C36: Table 1 | D36: Project Eldorado IRR 80-20
B37: Direct Costs 2026
C38: Table 1 | D38: Direct Costs 2026
B39: Trasnfers, Extras, Alco 2026
C40: Table 1 | D40: Trasnfers, Extras, Alco 2026
B41: Boats Data Sheet 2026
C42: Table 1 | D42: Boats Data Sheet 2026
B43: Allocation OH and Target 2026
C44: Table 1 | D44: Allocation OH and Target 2026
B45: Boats Data Sheet 2025
C46: Table 1 | D46: Boats Data Sheet 2025
...

Sheet RECOMMENDED PRICES
X1: Hidden comments
B2: TOUR | C2: BOAT CLASS | D2: AVERAGE TARGET TRIP RATE | E2: AVERAGE TARGET BOAT OCCUPANCY
B3: Shared | C3: Primary | D3: {=AVERAGE('Allocation OH and Target 2026'!I3:I23)} -> 0.6547619 | E3: {=AVERAGE('Allocation OH and Target 2026'!J3:J23)} -> 0.8047619
B4: Private | C4: Primary | D4: {=AVERAGE('Allocation OH and Target 2026'!I35:I53)} -> 0.66315789 | E4: N/A
B5: Private | C5: Secondary | D5: {=AVERAGE('Allocation OH and Target 2026'!I54,'Allocation OH and Target 2026'!I57:I59,'Allocation OH and Target 2026'!I62:I64,'Allocation OH and Target 2026'!I66,'Allocation OH and Target 2026'!I71:I77,'Allocation OH and Target 2026'!I82:I86,'Allocation OH and Target 2026'!I88:I91)} -> 0.1325 | E5: N/A
B7: STANDARD SHARED TOURS | C7: RECOMMENDED | D7: Actual Updated Prices | E7: TOTAL BASE for TripAdvisor (25%) | F7: TOTAL BASE for Klook (25%) | G7: TOTAL BASE for AirBnB (20%)
B8: PRICE PER PASSENGER | C8: {=ROUNDUP(AVERAGE('Shared Boats 2026 Target'!AG5:AG183,'Shared Boats 2026 Target'!AG212:AG367),-4)} -> 1460000 | D8: 1390000 | E8: {=D8/(100%-25%)} -> 1853333.3 | F8: {=D8/(100%-25%)} -> 1853333.3 | G8: {=D8/(100%-20%)} -> 1737500
B9: PRICES FOR HIGH SEASON +10% | D9: {=D8*110%} -> 1529000 | E9: {=E8*110%} -> 2038666.7 | F9: {=F8*110%} -> 2038666.7 | G9: {=G8*110%} -> 1911250
B11: PREMIUM SHARED TOURS | C11: RECOMMENDED | D11: Actual Updated Prices | E11: TOTAL BASE for TripAdvisor (25%) | F11: TOTAL BASE for Klook (25%) | G11: TOTAL BASE for AirBnB (20%)
B12: PRICE PER PASSENGER | C12: {=ROUNDUP(AVERAGE('Premium Shared 2026 Target'!AI1:AI183),-4)} -> 1910000 | D12: 2050000 | E12: {=D12/(100%-25%)} -> 2733333.3 | F12: {=D12/(100%-25%)} -> 2733333.3 | G12: {=D12/(100%-20%)} -> 2562500
B13: PRICES FOR HIGH SEASON +10% | D13: {=D12*110%} -> 2255000 | E13: {=E12*110%} -> 3006666.7 | F13: {=F12*110%} -> 3006666.7 | G13: {=G12*110%} -> 2818750
B15: PRIVATE TOURS | C15: Recommended | D15: Actual Updated Prices | E15: PRICES FOR HIGH SEASON +10% | F15: Actual Price at Bluuu.tours | G15: TO INCREASE/ TO DECREASE | H15: DTB10 Code NP.ONE Price | I15: PUBLISHED PRICE | K15: NET PROFIT | L15: NPM | M15: AGENT FEE % | N15: AGENT FEE | P15: PRICES FOR GETMYBOAT | R15: ABSOLUTE MINIMUM | Z15: PRICES FOR BALICOPTER
B16: Recommended Base Price:
B17: RECOMMENED BASE PRICE PER TOUR | C17: {=ROUNDUP(AVERAGE('Private Boats 2026 Target'!Z5,'Private Boats 2026 Target'!Z28,'Private Boats 2026 Target'!Z51,'Private Boats 2026 Target'!Z97,'Private Boats 2026 Target'!Z168,'Private Boats 2026 Target'!Z214,'Private Boats 2026 Target'!Z817,'Private Boats 2026 Target'!Z1008,'Private Boats 2026 Target'!Z1031,'Private Boats 2026 Target'!Z1054,'Private Boats 2026 Target'!Z1146),-4)} -> 12890000 | D17: {=10600000+500000+400000+400000+395000} -> 12295000 | E17: {=D17*110%} -> 13524500 | F17: {=12295000} -> 12295000 | G17: {=_xlfn.IFERROR((D17-F17),"not listed")} -> 0
B19: Recommended Boat Upgrade Price:
A20: O | B20: {='Boats Data Sheet 2025'!C3} -> Sweetheart 4 | C20: {=IF(ROUNDUP((AVERAGE('Private Boats 2026 Target'!AC5:AC22)-$C$17),-2)<0,0,ROUNDUP((AVERAGE('Private Boats 2026 Target'!AC5:AC22)-$C$17),-2))} -> 1190300 | D20: {=13000000-D17} -> 705000 | E20: {=D20*110%} -> 775500 | F20: 1500000 | G20: {=_xlfn.IFERROR((D20-F20),"not listed")} -> -795000 | H20: {=IF(A20="O",ROUND((F20+$F$17)/0.9-$F$17,-3),F20)} -> 3033000 | I20: {=$F$17+F20} -> 13795000 | K20: {=$F$17+F20-VLOOKUP(B20,'Private Boats 2026 Target'!$C$2:$AN$1501,38,0)} -> 3053191.4 | L20: {=K20/VLOOKUP(B20,'Private Boats 2026 Target'!$C$2:$AN$1501,38,0)} -> 0.28423439 | M20: 0.1 | N20: {=ROUND(($F$17+F20)*M20,-3)} -> 1380000 | P20: {=($F$17+F20)/14500} -> 951.37931 | R20: {=IF((C20-VLOOKUP(B20,'Private Boats 2026 Target'!$C$2:$AJ$714,32,0))<0,0,(C20-VLOOKUP(B20,'Private Boats 2026 Target'!$C$2:$AJ$714,32,0)))} -> 0 | Z20: {=($F$17+F20+($E$89-$E$88)-200000)*0.9} -> 12496500
A21: O | B21: {='Boats Data Sheet 2025'!C4} -> Riki J | C21: {=IF(ROUNDUP((AVERAGE('Private Boats 2026 Target'!AC28:AC45)-$C$17),-2)<0,0,ROUNDUP((AVERAGE('Private Boats 2026 Target'!AC28:AC45)-$C$17),-2))} -> 1886000 | D21: {=14500000-D17} -> 2205000 | E21: {=D21*110%} -> 2425500 | F21: 2700000 | G21: {=_xlfn.IFERROR((D21-F21),"not listed")} -> -495000 | H21: {=IF(A21="O",ROUND((F21+$F$17)/0.9-$F$17,-3),F21)} -> 4366000 | I21: {=$F$17+F21} -> 14995000 | K21: {=$F$17+F21-VLOOKUP(B21,'Private Boats 2026 Target'!$C$2:$AN$1501,38,0)} -> 3698814.7 | L21: {=K21/VLOOKUP(B21,'Private Boats 2026 Target'!$C$2:$AN$1501,38,0)} -> 0.32743927 | M21: 0.1 | N21: {=ROUND(($F$17+F21)*M21,-3)} -> 1500000 | P21: {=($F$17+F21)/14500} -> 1034.1379 | R21: {=IF((C21-VLOOKUP(B21,'Private Boats 2026 Target'!$C$2:$AJ$714,32,0))<0,0,(C21-VLOOKUP(B21,'Private Boats 2026 Target'!$C$2:$AJ$714,32,0)))} -> 0 | Z21: {=($F$17+F21+($E$89-$E$88)-200000)*0.95} -> 14330750
A22: O | B22: {='Boats Data Sheet 2025'!C11} -> Sanjaya | C22: {=IF(ROUNDUP((AVERAGE('Private Boats 2026 Target'!AC51:AC68)-$C$17),-2)<0,0,ROUNDUP((AVERAGE('Private Boats 2026 Target'!AC51:AC68)-$C$17),-2))} -> 614400 | D22: {=ROUNDUP(C22,-4)} -> 620000 | E22: {=D22*110%} -> 682000 | F22: 820000 | G22: {=_xlfn.IFERROR((D22-F22),"not listed")} -> -200000 | H22: {=IF(A22="O",ROUND((F22+$F$17)/0.9-$F$17,-3),F22)} -> 2277000 | I22: {=$F$17+F22} -> 13115000 | K22: {=$F$17+F22-VLOOKUP(B22,'Private Boats 2026 Target'!$C$2:$AN$1501,38,0)} -> 2744552.8 | L22: {=K22/VLOOKUP(B22,'Private Boats 2026 Target'!$C$2:$AN$1501,38,0)} -> 0.26465135 | M22: 0.1 | N22: {=ROUND(($F$17+F22)*M22,-3)} -> 1312000 | P22: {=($F$17+F22)/14500} -> 904.48276 | R22: {=IF((C22-VLOOKUP(B22,'Private Boats 2026 Target'!$C$2:$AJ$714,32,0))<0,0,(C22-VLOOKUP(B22,'Private Boats 2026 Target'!$C$2:$AJ$714,32,0)))} -> 0 | Z22: {=($F$17+F22+($E$89-$E$88)-200000)*0.95} -> 12544750
A23: O | B23: {='Boats Data Sheet 2025'!C24} -> Lady Manta | C23: {=IF(ROUNDUP((AVERAGE('Shared Boats 2026 Target'!AD143:AD148)-$C$17),-2)<0,0,ROUNDUP((AVERAGE('Shared Boats 2026 Target'!AD143:AD148)-$C$17),-2))} -> 0 | D23: {=ROUNDUP(C23,-4)} -> 0 | E23: {=D23*110%} -> 0 | F23: 1200000 | G23: {=_xlfn.IFERROR((D23-F23),"not listed")} -> -1200000 | H23: {=IF(A23="O",ROUND((F23+$F$17)/0.9-$F$17,-3),F23)} -> 2699000 | I23: {=$F$17+F23} -> 13495000 | K23: {=$F$17+F23-AVERAGE('Shared Boats 2026 Target'!Z143:AA148)} -> 5167952.6 | L23: {=K23/AVERAGE('Shared Boats 2026 Target'!AA143:AA148)} -> 0.62062246 | M23: 0.1 | N23: {=ROUND(($F$17+F23)*M23,-3)} -> 1350000 | P23: {=($F$17+F23)/14500} -> 930.68966 | Z23: {=($F$17+F23+($E$89-$E$88)-200000)*0.9} -> 12226500
A24: O | B24: {='Boats Data Sheet 2025'!C12} -> Jayanadi | C24: {=IF(ROUNDUP((AVERAGE('Private Boats 2026 Target'!AC74:AC91)-$C$17),-2)<0,0,ROUNDUP((AVERAGE('Private Boats 2026 Target'!AC74:AC91)-$C$17),-2))} -> 1894500 | D24: {=13000000-D17} -> 705000 | E24: {=D24*110%} -> 775500 | F24: 1835000 | G24: {=_xlfn.IFERROR((D24-F24),"not listed")} -> -1130000 | H24: {=IF(A24="O",ROUND((F24+$F$17)/0.9-$F$17,-3),F24)} -> 3405000 | I24: {=$F$17+F24} -> 14130000 | K24: {=$F$17+F24-VLOOKUP(B24,'Private Boats 2026 Target'!$C$2:$AN$1501,38,0)} -> 2739552.8 | L24: {=K24/VLOOKUP(B24,'Private Boats 2026 Target'!$C$2:$AN$1501,38,0)} -> 0.2405132 | M24: 0.1 | N24: {=ROUND(($F$17+F24)*M24,-3)} -> 1413000 | P24: {=($F$17+F24)/14500} -> 974.48276 | R24: {=IF((C24-VLOOKUP(B24,'Private Boats 2026 Target'!$C$2:$AJ$714,32,0))<0,0,(C24-VLOOKUP(B24,'Private Boats 2026 Target'!$C$2:$AJ$714,32,0)))} -> 36437.5 | Z24: {=($F$17+F24+($E$89-$E$88)-200000)*0.95} -> 13509000
A25: O | B25: {='Boats Data Sheet 2025'!C13} -> Sea Dragon | C25: {=IF(ROUNDUP((AVERAGE('Private Boats 2026 Target'!AC97:AC114)-$C$17),-2)<0,0,ROUNDUP((AVERAGE('Private Boats 2026 Target'!AC97:AC114)-$C$17),-2))} -> 614400 | D25: {=ROUNDUP(C25,-4)} -> 620000 | E25: {=D25*110%} -> 682000 | F25: 820000 | G25: {=_xlfn.IFERROR((D25-F25),"not listed")} -> -200000 | H25: {=IF(A25="O",ROUND((F25+$F$17)/0.9-$F$17,-3),F25)} -> 2277000 | I25: {=$F$17+F25} -> 13115000 | K25: {=$F$17+F25-VLOOKUP(B25,'Private Boats 2026 Target'!$C$2:$AN$1501,38,0)} -> 2744552.8 | L25: {=K25/VLOOKUP(B25,'Private Boats 2026 Target'!$C$2:$AN$1501,38,0)} -> 0.26465135 | M25: 0.1 | N25: {=ROUND(($F$17+F25)*M25,-3)} -> 1312000 | P25: {=($F$17+F25)/14500} -> 904.48276 | R25: {=IF((C25-VLOOKUP(B25,'Private Boats 2026 Target'!$C$2:$AJ$714,32,0))<0,0,(C25-VLOOKUP(B25,'Private Boats 2026 Target'!$C$2:$AJ$714,32,0)))} -> 0 | Z25: {=($F$17+F25+($E$89-$E$88)-200000)*0.95} -> 12544750
A26: O | B26: Sanjaya O4 | C26: {=IF(ROUNDUP((AVERAGE('Private Boats 2026 Target'!AC916:AC933)-$C$17),-2)<0,0,ROUNDUP((AVERAGE('Private Boats 2026 Target'!AC916:AC933)-$C$17),-2))} -> 3359500 | D26: {=ROUNDUP(C26,-4)} -> 3360000 | E26: {=D26*110%} -> 3696000 | F26: 4460000 | G26: {=_xlfn.IFERROR((D26-F26),"not listed")} -> -1100000 | H26: {=IF(A26="O",ROUND((F26+$F$17)/0.9-$F$17,-3),F26)} -> 6322000 | I26: {=$F$17+F26} -> 16755000 | K26: {=$F$17+F26-VLOOKUP(B26,'Private Boats 2026 Target'!$C$2:$AN$1501,38,0)} -> 4284719.5 | L26: {=K26/VLOOKUP(B26,'Private Boats 2026 Target'!$C$2:$AN$1501,38,0)} -> 0.34359448 | M26: 0.1 | N26: {=ROUND(($F$17+F26)*M26,-3)} -> 1676000 | P26: {=($F$17+F26)/14500} -> 1155.5172 | R26: {=IF((C26-VLOOKUP(B26,'Private Boats 2026 Target'!$C$2:$AJ$714,32,0))<0,0,(C26-VLOOKUP(B26,'Private Boats 2026 Target'!$C$2:$AJ$714,32,0)))} | Z26: {=($F$17+F26+($E$89-$E$88)-200000)*0.95} -> 16002750
A27: O | B27: Sanjaya O5 | C27: {=IF(ROUNDUP((AVERAGE('Private Boats 2026 Target'!AC962:AC979)-$C$17),-2)<0,0,ROUNDUP((AVERAGE('Private Boats 2026 Target'!AC962:AC979)-$C$17),-2))} -> 3359500 | D27: {=ROUNDUP(C27,-4)} -> 3360000 | E27: {=D27*110%} -> 3696000 | F27: 4460000 | G27: {=_xlfn.IFERROR((D27-F27),"not listed")} -> -1100000 | H27: {=IF(A27="O",ROUND((F27+$F$17)/0.9-$F$17,-3),F27)} -> 6322000 | I27: {=$F$17+F27} -> 16755000 | K27: {=$F$17+F27-VLOOKUP(B27,'Private Boats 2026 Target'!$C$2:$AN$1501,38,0)} -> 4284719.5 | L27: {=K27/VLOOKUP(B27,'Private Boats 2026 Target'!$C$2:$AN$1501,38,0)} -> 0.34359448 | M27: 0.1 | N27: {=ROUND(($F$17+F27)*M27,-3)} -> 1676000 | P27: {=($F$17+F27)/14500} -> 1155.5172 | R27: {=IF((C27-VLOOKUP(B27,'Private Boats 2026 Target'!$C$2:$AJ$714,32,0))<0,0,(C27-VLOOKUP(B27,'Private Boats 2026 Target'!$C$2:$AJ$714,32,0)))} | Z27: {=($F$17+F27+($E$89-$E$88)-200000)*0.95} -> 16002750
A28: O | B28: Almond Milk | C28: {=IF(ROUNDUP((AVERAGE('Private Boats 2026 Target'!AC1008:AC1025)-$C$17),-2)<0,0,ROUNDUP((AVERAGE('Private Boats 2026 Target'!AC1008:AC1025)-$C$17),-2))} -> 1085000 | D28: {=ROUNDUP(C28,-4)} -> 1090000 | E28: {=D28*110%} -> 1199000 | F28: 4160000 | G28: {=_xlfn.IFERROR((D28-F28),"not listed")} -> -3070000 | H28: {=IF(A28="O",ROUND((F28+$F$17)/0.9-$F$17,-3),F28)} -> 5988000 | I28: {=$F$17+F28} -> 16455000 | K28: {=$F$17+F28-VLOOKUP(B28,'Private Boats 2026 Target'!$C$2:$AN$1501,38,0)} -> 5797112.6 | L28: {=K28/VLOOKUP(B28,'Private Boats 2026 Target'!$C$2:$AN$1501,38,0)} -> 0.54392698 | M28: 0.1 | N28: {=ROUND(($F$17+F28)*M28,-3)} -> 1646000 | P28: {=($F$17+F28)/14500} -> 1134.8276 | R28: {=IF((C28-VLOOKUP(B28,'Private Boats 2026 Target'!$C$2:$AJ$714,32,0))<0,0,(C28-VLOOKUP(B28,'Private Boats 2026 Target'!$C$2:$AJ$714,32,0)))} | Z28: {=($F$17+F28+($E$89-$E$88)-200000)*0.9} -> 14890500
A29: O | B29: Honey Milk | C29: {=IF(ROUNDUP((AVERAGE('Private Boats 2026 Target'!AC1031:AC1048)-$C$17),-2)<0,0,ROUNDUP((AVERAGE('Private Boats 2026 Target'!AC1031:AC1048)-$C$17),-2))} -> 1085000 | D29: {=ROUNDUP(C29,-4)} -> 1090000 | E29: {=D29*110%} -> 1199000 | F29: 4160000 | G29: {=_xlfn.IFERROR((D29-F29),"not listed")} -> -3070000 | H29: {=IF(A29="O",ROUND((F29+$F$17)/0.9-$F$17,-3),F29)} -> 5988000 | I29: {=$F$17+F29} -> 16455000 | K29: {=$F$17+F29-VLOOKUP(B29,'Private Boats 2026 Target'!$C$2:$AN$1501,38,0)} -> 5797112.6 | L29: {=K29/VLOOKUP(B29,'Private Boats 2026 Target'!$C$2:$AN$1501,38,0)} -> 0.54392698 | M29: 0.1 | N29: {=ROUND(($F$17+F29)*M29,-3)} -> 1646000 | P29: {=($F$17+F29)/14500} -> 1134.8276 | R29: {=IF((C29-VLOOKUP(B29,'Private Boats 2026 Target'!$C$2:$AJ$714,32,0))<0,0,(C29-VLOOKUP(B29,'Private Boats 2026 Target'!$C$2:$AJ$714,32,0)))} | Z29: {=($F$17+F29+($E$89-$E$88)-200000)*0.9} -> 14890500
A30: O | B30: Eldorado 1 | C30: {=IF(ROUNDUP((AVERAGE('Private Boats 2026 Target'!AC1054:AC1071)-$C$17),-2)<0,0,ROUNDUP((AVERAGE('Private Boats 2026 Target'!AC1054:AC1071)-$C$17),-2))} -> 745700 | D30: {=ROUNDUP(C30,-4)} -> 750000 | E30: {=D30*110%} -> 825000 | F30: 4160000 | G30: {=_xlfn.IFERROR((D30-F30),"not listed")} -> -3410000 | H30: {=IF(A30="O",ROUND((F30+$F$17)/0.9-$F$17,-3),F30)} -> 5988000 | I30: {=$F$17+F30} -> 16455000 | K30: {=$F$17+F30-VLOOKUP(B30,'Private Boats 2026 Target'!$C$2:$AN$1501,38,0)} -> 6067457.4 | L30: {=K30/VLOOKUP(B30,'Private Boats 2026 Target'!$C$2:$AN$1501,38,0)} -> 0.58410903 | M30: 0.1 | N30: {=ROUND(($F$17+F30)*M30,-3)} -> 1646000 | P30: {=($F$17+F30)/14500} -> 1134.8276 | R30: {=IF((C30-VLOOKUP(B30,'Private Boats 2026 Target'!$C$2:$AJ$714,32,0))<0,0,(C30-VLOOKUP(B30,'Private Boats 2026 Target'!$C$2:$AJ$714,32,0)))} | Z30: {=($F$17+F30+($E$89-$E$88)-200000)*0.9} -> 14890500
A31: O | B31: Eldorado 2 - Arya | C31: {=IF(ROUNDUP((AVERAGE('Private Boats 2026 Target'!AC1077:AC1094)-$C$17),-2)<0,0,ROUNDUP((AVERAGE('Private Boats 2026 Target'!AC1100:AC1117)-$C$17),-2))} -> 986400 | D31: {=ROUNDUP(C31,-4)} -> 990000 | E31: {=D31*110%} -> 1089000 | F31: 4160000 | G31: {=_xlfn.IFERROR((D31-F31),"not listed")} -> -3170000 | H31: {=IF(A31="O",ROUND((F31+$F$17)/0.9-$F$17,-3),F31)} -> 5988000 | I31: {=$F$17+F31} -> 16455000 | K31: {=$F$17+F31-VLOOKUP(B31,'Private Boats 2026 Target'!$C$2:$AN$1501,38,0)} -> 5875613 | L31: {=K31/VLOOKUP(B31,'Private Boats 2026 Target'!$C$2:$AN$1501,38,0)} -> 0.55538312 | M31: 0.1 | N31: {=ROUND(($F$17+F31)*M31,-3)} -> 1646000 | P31: {=($F$17+F31)/14500} -> 1134.8276 | R31: {=IF((C31-VLOOKUP(B31,'Private Boats 2026 Target'!$C$2:$AJ$714,32,0))<0,0,(C31-VLOOKUP(B31,'Private Boats 2026 Target'!$C$2:$AJ$714,32,0)))} | Z31: {=($F$17+F31+($E$89-$E$88)-200000)*0.9} -> 14890500
A32: O | B32: Eldorado 3 - Evgenii | C32: {=IF(ROUNDUP((AVERAGE('Private Boats 2026 Target'!AC1100:AC1117)-$C$17),-2)<0,0,ROUNDUP((AVERAGE('Private Boats 2026 Target'!AC1100:AC1117)-$C$17),-2))} -> 986400 | D32: {=ROUNDUP(C32,-4)} -> 990000 | E32: {=D32*110%} -> 1089000 | F32: 4160000 | G32: {=_xlfn.IFERROR((D32-F32),"not listed")} -> -3170000 | H32: {=IF(A32="O",ROUND((F32+$F$17)/0.9-$F$17,-3),F32)} -> 5988000 | I32: {=$F$17+F32} -> 16455000 | K32: {=$F$17+F32-VLOOKUP(B32,'Private Boats 2026 Target'!$C$2:$AN$1501,38,0)} -> 5875613 | L32: {=K32/VLOOKUP(B32,'Private Boats 2026 Target'!$C$2:$AN$1501,38,0)} -> 0.55538312 | M32: 0.1 | N32: {=ROUND(($F$17+F32)*M32,-3)} -> 1646000 | P32: {=($F$17+F32)/14500} -> 1134.8276 | R32: {=IF((C32-VLOOKUP(B32,'Private Boats 2026 Target'!$C$2:$AJ$714,32,0))<0,0,(C32-VLOOKUP(B32,'Private Boats 2026 Target'!$C$2:$AJ$714,32,0)))} | Z32: {=($F$17+F32+($E$89-$E$88)-200000)*0.9} -> 14890500
A33: O | B33: Eldorado 4 - Vadim | C33: {=IF(ROUNDUP((AVERAGE('Private Boats 2026 Target'!AC1123:AC1140)-$C$17),-2)<0,0,ROUNDUP((AVERAGE('Private Boats 2026 Target'!AC1123:AC1140)-$C$17),-2))} -> 1431200 | D33: {=ROUNDUP(C33,-4)} -> 1440000 | E33: {=D33*110%} -> 1584000 | F33: 4160000 | G33: {=_xlfn.IFERROR((D33-F33),"not listed")} -> -2720000 | H33: {=IF(A33="O",ROUND((F33+$F$17)/0.9-$F$17,-3),F33)} -> 5988000 | I33: {=$F$17+F33} -> 16455000 | K33: {=$F$17+F33-VLOOKUP(B33,'Private Boats 2026 Target'!$C$2:$AN$1501,38,0)} -> 5521186.6 | L33: {=K33/VLOOKUP(B33,'Private Boats 2026 Target'!$C$2:$AN$1501,38,0)} -> 0.50496441 | M33: 0.1 | N33: {=ROUND(($F$17+F33)*M33,-3)} -> 1646000 | P33: {=($F$17+F33)/14500} -> 1134.8276 | R33: {=IF((C33-VLOOKUP(B33,'Private Boats 2026 Target'!$C$2:$AJ$714,32,0))<0,0,(C33-VLOOKUP(B33,'Private Boats 2026 Target'!$C$2:$AJ$714,32,0)))} | Z33: {=($F$17+F33+($E$89-$E$88)-200000)*0.9} -> 14890500
B34: Eldorado 5 - Robert | C34: {=IF(ROUNDUP((AVERAGE('Private Boats 2026 Target'!AC1286:AC1303)-$C$17),-2)<0,0,ROUNDUP((AVERAGE('Private Boats 2026 Target'!AC1286:AC1303)-$C$17),-2))} -> 4438800 | D34: {=ROUNDUP(C34,-4)} -> 4440000 | E34: {=D34*110%} -> 4884000 | F34: 4160000 | G34: {=_xlfn.IFERROR((D34-F34),"not listed")} -> 280000 | H34: {=IF(A34="O",ROUND((F34+$F$17)/0.9-$F$17,-3),F34)} -> 4160000 | I34: {=$F$17+F34} -> 16455000 | K34: {=$F$17+F34-VLOOKUP(B34,'Private Boats 2026 Target'!$C$2:$AN$1501,38,0)} -> 3124719.5 | L34: {=K34/VLOOKUP(B34,'Private Boats 2026 Target'!$C$2:$AN$1501,38,0)} -> 0.23440763 | M34: 0.1 | N34: {=ROUND(($F$17+F34)*M34,-3)} -> 1646000 | P34: {=($F$17+F34)/14500} -> 1134.8276 | R34: {=IF((C34-VLOOKUP(B34,'Private Boats 2026 Target'!$C$2:$AJ$714,32,0))<0,0,(C34-VLOOKUP(B34,'Private Boats 2026 Target'!$C$2:$AJ$714,32,0)))} | Z34: {=($F$17+F34+($E$89-$E$88)-200000)*0.9} -> 14890500
B35: Eldorado 6 - Vadim | C35: {=IF(ROUNDUP((AVERAGE('Private Boats 2026 Target'!AC1309:AC1326)-$C$17),-2)<0,0,ROUNDUP((AVERAGE('Private Boats 2026 Target'!AC1309:AC1326)-$C$17),-2))} -> 4438800 | D35: {=ROUNDUP(C35,-4)} -> 4440000 | E35: {=D35*110%} -> 4884000 | F35: 4160000 | G35: {=_xlfn.IFERROR((D35-F35),"not listed")} -> 280000 | H35: {=IF(A35="O",ROUND((F35+$F$17)/0.9-$F$17,-3),F35)} -> 4160000 | I35: {=$F$17+F35} -> 16455000 | K35: {=$F$17+F35-VLOOKUP(B35,'Private Boats 2026 Target'!$C$2:$AN$1501,38,0)} -> 3124719.5 | L35: {=K35/VLOOKUP(B35,'Private Boats 2026 Target'!$C$2:$AN$1501,38,0)} -> 0.23440763 | M35: 0.1 | N35: {=ROUND(($F$17+F35)*M35,-3)} -> 1646000 | P35: {=($F$17+F35)/14500} -> 1134.8276 | R35: {=IF((C35-VLOOKUP(B35,'Private Boats 2026 Target'!$C$2:$AJ$714,32,0))<0,0,(C35-VLOOKUP(B35,'Private Boats 2026 Target'!$C$2:$AJ$714,32,0)))} | Z35: {=($F$17+F35+($E$89-$E$88)-200000)*0.9} -> 14890500
B36: Boat Angels | C36: {=IF(ROUNDUP((AVERAGE('Private Boats 2026 Target'!AC1263:AC1280)-$C$17),-2)<0,0,ROUNDUP((AVERAGE('Private Boats 2026 Target'!AC1263:AC1280)-$C$17),-2))} -> 0 | D36: {=ROUNDUP(C36,-4)} -> 0 | E36: {=D36*110%} -> 0 | F36: 4160000 | G36: {=_xlfn.IFERROR((D36-F36),"not listed")} -> -4160000 | H36: {=IF(A36="O",ROUND((F36+$F$17)/0.9-$F$17,-3),F36)} -> 4160000 | I36: {=$F$17+F36} -> 16455000 | K36: {=$F$17+F36-VLOOKUP(B36,'Private Boats 2026 Target'!$C$2:$AN$1501,38,0)} -> 6847319.5 | L36: {=K36/VLOOKUP(B36,'Private Boats 2026 Target'!$C$2:$AN$1501,38,0)} -> 0.71269226 | M36: 0.1 | N36: {=ROUND(($F$17+F36)*M36,-3)} -> 1646000 | P36: {=($F$17+F36)/14500} -> 1134.8276 | R36: {=IF((C36-VLOOKUP(B36,'Private Boats 2026 Target'!$C$2:$AJ$714,32,0))<0,0,(C36-VLOOKUP(B36,'Private Boats 2026 Target'!$C$2:$AJ$714,32,0)))} | Z36: {=($F$17+F36+($E$89-$E$88)-200000)*0.9} -> 14890500
A37: D | B37: {='Boats Data Sheet 2025'!C19} -> Seven Heaven | C37: {=IF(ROUNDUP((AVERAGE('Private Boats 2026 Target'!AC120:AC139)-$C$17),-2)<0,0,ROUNDUP((AVERAGE('Private Boats 2026 Target'!AC120:AC139)-$C$17),-2))} -> 2304300 | D37: {=26000000-D17} -> 13705000 | E37: {=D37*110%} -> 15075500 | F37: Delisted | G37: Delisted | H37: Delisted | I37: Delisted | K37: Delisted | L37: Delisted | M37: Delisted | N37: Delisted | P37: Delisted | R37: Delisted
A38: D | B38: {='Boats Data Sheet 2025'!C20} -> Mironia | C38: {=IF(ROUNDUP((AVERAGE('Private Boats 2026 Target'!AC145:AC162)-$C$17),-2)<0,0,ROUNDUP((AVERAGE('Private Boats 2026 Target'!AC145:AC162)-$C$17),-2))} -> 4908400 | D38: {=ROUNDUP(C38,-4)} -> 4910000 | E38: {=D38*110%} -> 5401000 | F38: Delisted | G38: Delisted | H38: Delisted | I38: Delisted | K38: Delisted | L38: Delisted | M38: Delisted | N38: Delisted | P38: Delisted | R38: Delisted
A39: O | B39: {='Boats Data Sheet 2025'!C21} -> Little Star | C39: {=IF(ROUNDUP((AVERAGE('Private Boats 2026 Target'!AC168:AC185)-$C$17),-2)<0,0,ROUNDUP((AVERAGE('Private Boats 2026 Target'!AC168:AC185)-$C$17),-2))} -> 6400 | D39: {=ROUNDUP(C39,-4)} -> 10000 | E39: {=D39*110%} -> 11000 | F39: -1000000 | G39: {=_xlfn.IFERROR((D39-F39),"not listed")} -> 1010000 | H39: {=IF(A39="O",ROUND((F39+$F$17)/0.9-$F$17,-3),F39)} -> 255000 | I39: {=$F$17+F39} -> 11295000 | K39: {=$F$17+F39-VLOOKUP(B39,'Private Boats 2026 Target'!$C$2:$AN$1501,38,0)} -> 1409052.8 | L39: {=K39/VLOOKUP(B39,'Private Boats 2026 Target'!$C$2:$AN$1501,38,0)} -> 0.14253089 | M39: No fee | N39: No fee | P39: {=($F$17+F39)/14500} -> 778.96552 | R39: {=IF((C39-VLOOKUP(B39,'Private Boats 2026 Target'!$C$2:$AJ$714,32,0))<0,0,(C39-VLOOKUP(B39,'Private Boats 2026 Target'!$C$2:$AJ$714,32,0)))} -> 6400 | Z39: {=($F$17+F39+($E$89-$E$88)-200000)*0.95} -> 10815750 | AA39: Notes KT:
A40: P | B40: {='Boats Data Sheet 2025'!C22} -> Rara | C40: {=IF(ROUNDUP((AVERAGE('Private Boats 2026 Target'!AC191:AC208)-$C$17),-2)<0,0,ROUNDUP((AVERAGE('Private Boats 2026 Target'!AC191:AC208)-$C$17),-2))} -> 1670500 | D40: {=ROUNDUP(C40,-4)} -> 1680000 | E40: {=D40*110%} -> 1848000 | F40: 1740000 | G40: {=_xlfn.IFERROR((D40-F40),"not listed")} -> -60000 | H40: {=IF(A40="O",ROUND((F40+$F$17)/0.9-$F$17,-3),F40)} -> 1740000 | I40: {=$F$17+F40} -> 14035000 | K40: {=$F$17+F40-VLOOKUP(B40,'Private Boats 2026 Target'!$C$2:$AN$1501,38,0)} -> 2823052.8 | L40: {=K40/VLOOKUP(B40,'Private Boats 2026 Target'!$C$2:$AN$1501,38,0)} -> 0.2517897 | M40: No fee | N40: No fee | P40: {=($F$17+F40)/14500} -> 967.93103 | R40: {=IF((C40-VLOOKUP(B40,'Private Boats 2026 Target'!$C$2:$AJ$714,32,0))<0,0,(C40-VLOOKUP(B40,'Private Boats 2026 Target'!$C$2:$AJ$714,32,0)))} -> 233875 | AA40: Rara was decreased by 1.3 jt. as recommended (old boat with too many complains) -> confirmed with Viod and Rozen
A41: O | B41: {='Boats Data Sheet 2025'!C23} -> Small Sweetheart | C41: {=IF(ROUNDUP((AVERAGE('Private Boats 2026 Target'!AC214:AC231)-$C$17),-2)<0,0,ROUNDUP((AVERAGE('Private Boats 2026 Target'!AC214:AC231)-$C$17),-2))} -> 0 | D41: {=ROUNDUP(C41,-4)} -> 0 | E41: {=D41*110%} -> 0 | F41: -1100000 | G41: {=_xlfn.IFERROR((D41-F41),"not listed")} -> 1100000 | H41: {=IF(A41="O",ROUND((F41+$F$17)/0.9-$F$17,-3),F41)} -> 144000 | I41: {=$F$17+F41} -> 11195000 | K41: {=$F$17+F41-VLOOKUP(B41,'Private Boats 2026 Target'!$C$2:$AN$1501,38,0)} -> 1615052.8 | L41: {=K41/VLOOKUP(B41,'Private Boats 2026 Target'!$C$2:$AN$1501,38,0)} -> 0.16858682 | M41: No fee | N41: No fee | P41: {=($F$17+F41)/14500} -> 772.06897 | R41: {=IF((C41-VLOOKUP(B41,'Private Boats 2026 Target'!$C$2:$AJ$714,32,0))<0,0,(C41-VLOOKUP(B41,'Private Boats 2026 Target'!$C$2:$AJ$714,32,0)))} -> 0 | Z41: {=($F$17+F41+($E$89-$E$88)-200000)*0.95} -> 10720750
A42: O | B42: {='Boats Data Sheet 2025'!C26} -> Dedean | C42: {=IF(ROUNDUP((AVERAGE('Private Boats 2026 Target'!AC237:AC254)-$C$17),-2)<0,0,ROUNDUP((AVERAGE('Private Boats 2026 Target'!AC237:AC254)-$C$17),-2))} -> 710400 | D42: {=14500000-D17} -> 2205000 | E42: {=D42*110%} -> 2425500 | F42: Delisted | G42: Delisted | H42: Delisted | I42: Delisted | K42: Delisted | L42: Delisted | M42: Delisted | N42: Delisted | P42: {=($F$17+F42)/14500} | R42: {=IF((C42-VLOOKUP(B42,'Private Boats 2026 Target'!$C$2:$AJ$714,32,0))<0,0,(C42-VLOOKUP(B42,'Private Boats 2026 Target'!$C$2:$AJ$714,32,0)))} -> 0
A43: P | B43: {='Boats Data Sheet 2025'!C27} -> King Fish | C43: {=IF(ROUNDUP((AVERAGE('Private Boats 2026 Target'!AC260:AC277)-$C$17),-2)<0,0,ROUNDUP((AVERAGE('Private Boats 2026 Target'!AC260:AC277)-$C$17),-2))} -> 11948900 | D43: {=ROUNDUP(C43,-4)} -> 11950000 | E43: {=D43*110%} -> 13145000 | F43: 10840000 | G43: {=_xlfn.IFERROR((D43-F43),"not listed")} -> 1110000 | H43: {=IF(A43="O",ROUND((F43+$F$17)/0.9-$F$17,-3),F43)} -> 10840000 | I43: {=$F$17+F43} -> 23135000 | K43: {=$F$17+F43-VLOOKUP(B43,'Private Boats 2026 Target'!$C$2:$AN$1501,38,0)} -> 3733052.8 | L43: {=K43/VLOOKUP(B43,'Private Boats 2026 Target'!$C$2:$AN$1501,38,0)} -> 0.19240609 | M43: 0.05 | N43: {=ROUND(($F$17+F43)*M43,-3)} -> 1157000 | P43: {=($F$17+F43)/14500} -> 1595.5172 | R43: {=IF((C43-VLOOKUP(B43,'Private Boats 2026 Target'!$C$2:$AJ$714,32,0))<0,0,(C43-VLOOKUP(B43,'Private Boats 2026 Target'!$C$2:$AJ$714,32,0)))} -> 10184471 | AA43: Increased by 1.5 jt. tho we still accept it's a lower margin boat -> to follow up bookings stats in May -> confirmed with Void
A44: O | B44: {='Boats Data Sheet 2025'!C28} -> Big Little Star | C44: {=IF(ROUNDUP((AVERAGE('Private Boats 2026 Target'!AC283:AC300)-$C$17),-2)<0,0,ROUNDUP((AVERAGE('Private Boats 2026 Target'!AC283:AC300)-$C$17),-2))} -> 652100 | D44: {=ROUNDUP(C44,-4)} -> 660000 | E44: {=D44*110%} -> 726000 | F44: 920000 | G44: {=_xlfn.IFERROR((D44-F44),"not listed")} -> -260000 | H44: {=IF(A44="O",ROUND((F44+$F$17)/0.9-$F$17,-3),F44)} -> 2388000 | I44: {=$F$17+F44} -> 13215000 | K44: {=$F$17+F44-VLOOKUP(B44,'Private Boats 2026 Target'!$C$2:$AN$1501,38,0)} -> 2814552.8 | L44: {=K44/VLOOKUP(B44,'Private Boats 2026 Target'!$C$2:$AN$1501,38,0)} -> 0.27061845 | M44: 0.1 | N44: {=ROUND(($F$17+F44)*M44,-3)} -> 1322000 | P44: {=($F$17+F44)/14500} -> 911.37931 | R44: {=IF((C44-VLOOKUP(B44,'Private Boats 2026 Target'!$C$2:$AJ$714,32,0))<0,0,(C44-VLOOKUP(B44,'Private Boats 2026 Target'!$C$2:$AJ$714,32,0)))} -> 652100 | Z44: {=($F$17+F44+($E$89-$E$88)-200000)*0.95} -> 12639750
...

Sheet PnL 2026 Plan-Forecast
B2: PROFIT AND LOSS STATEMENT | C2: 2026 FORECAST AND PLAN | D2: % | F2: Delivered Quantity
B4: SALES REVENUE | INCOME | C4: {=SUM(C24,C80,C93,C108,C117,C119,C121,C144)} -> 9.4173591e+10
B6: Private Tour - Base Price (AirBnb) | C6: {=F6*'RECOMMENDED PRICES'!$M$93} -> 25637953 | D6: {=F6/$F$24} -> 0.00066294724 | F6: {=$F$24*'Actual Sales 2025'!D7} -> 1.5620694
B7: Less: AirBnB servive comission (20%) | C7: {=-C6*20%} -> -5127590.5
B8: Private Tour - Base Price (WhatsApp) | C8: {=F8*'RECOMMENDED PRICES'!$E$93} -> 9640449.2 | D8: {=F8/$F$24} -> 0.00029766732 | F8: {=$F$24*'Actual Sales 2025'!D8} -> 0.70137862
B9: Private Tour - Base Price (Nusapenida.one) | C9: {=F9*'RECOMMENDED PRICES'!$E$93} -> 0 | D9: {=F9/$F$24} -> 0 | F9: {=$F$24*0} -> 0
B10: Private Tour - Base Price (GetMyBoat) | C10: {=F10*'RECOMMENDED PRICES'!$F$93} -> 80709442 | D10: {=F10/$F$24} -> 0.0024911523 | F10: {=$F$24*'Actual Sales 2025'!D9} -> 5.8697776
B11: Private Tour - Base Price (Bluuu.tours) | C11: {=F11*'RECOMMENDED PRICES'!$E$93} -> 2.6627741e+10 | D11: {=F11/$F$24} -> 0.82218247 | F11: {=$F$24*('Actual Sales 2025'!D19+'Actual Sales 2025'!D10+'Actual Sales 2025'!D16)} -> 1937.2674
B12: Less: discount (10%) | C12: {=-C11*10%} -> -2.6627741e+09
B13: Private Tour - Base Price (Klook) | C13: {=F13*'RECOMMENDED PRICES'!L93} -> 2.3571893e+08 | D13: {=F13/$F$24} -> 0.0060952297 | F13: {=$F$24*'Actual Sales 2025'!D11} -> 14.361885
B14: Less: Klook servive comission (20%) | C14: {=-C13*20%} -> -47143785
B15: Private Tour - Base Price (TripAdvisor (pv)) | C15: {=F15*'RECOMMENDED PRICES'!K93} -> 6.1582142e+09 | D15: {=F15/$F$24} -> 0.15661973 | F15: {=$F$24*'Actual Sales 2025'!D12} -> 369.03525
B16: Less: TripAdvisor servive comission (25%) | C16: {=-C15*25%} -> -1.5395535e+09
B17: Private Tour - Base Price (Instagram) | C17: {=F17*'RECOMMENDED PRICES'!$E$93} -> 48842468 | D17: {=F17/$F$24} -> 0.0015081047 | F17: {=$F$24*'Actual Sales 2025'!D15} -> 3.5534717
B18: Private Tour - Base Price (MyBaliTrips) | C18: 0 | D18: 0 | F18: {=$F$24*0} -> 0
B19: Private Tour - Base Price (ClickAndBoat) | C19: {=F19*'RECOMMENDED PRICES'!$E$93} -> 1.0379965e+08 | D19: 0 | F19: {=$F$24*'Actual Sales 2025'!D14} -> 7.5518118
B20: Private Tour - Base Price (LuxEscapes) | C20: {=F20*'RECOMMENDED PRICES'!$E$93} -> 52488952 | D20: {=F20/$F$24} -> 0.0016206969 | F20: {=$F$24*'Actual Sales 2025'!D17} -> 3.818767
B21: Private Tour - Base Price (Vio) | C21: {=F21*'RECOMMENDED PRICES'!$E$93} -> 13096722 | D21: {=F21/$F$24} -> 0.00040438635 | F21: {=$F$24*'Actual Sales 2025'!D18} -> 0.95283535
B22: Private Tour - Base Price (GetYourGuide) | C22: {=F22*'RECOMMENDED PRICES'!$K$93} -> 1.931611e+08 | D22: {=F22/$F$24} -> 0.0049125995 | F22: {=$F$24*'Actual Sales 2025'!D13} -> 11.575312
B23: Less: GYG servive comission (30%) | C23: {=-C22*25%} -> -48290274
B24: Private Tour Base Price Total | C24: {=SUM(C6:C22)} -> 2.9294452e+10 | D24: {=F24/$F$24} -> 1 | F24: {='Allocation OH and Target 2026'!K92} -> 2356.25
B26: Sweetheart 4 | C26: {=_xlfn.IFERROR((VLOOKUP(B26,'RECOMMENDED PRICES'!$B$20:$F$58,5,0)*F26),0)} -> 42000000 | D26: {=C26/$C$80} -> 0.0042887755 | F26: {=VLOOKUP(B26,'Allocation OH and Target 2026'!$C$35:$K$87,9,0)} -> 28
B27: Riki J | C27: {=_xlfn.IFERROR((VLOOKUP(B27,'RECOMMENDED PRICES'!$B$20:$F$58,5,0)*F27),0)} -> 153900000 | D27: {=C27/$C$80} -> 0.015715299 | F27: {=VLOOKUP(B27,'Allocation OH and Target 2026'!$C$35:$K$91,9,0)} -> 57
B28: Sanjaya | C28: {=_xlfn.IFERROR((VLOOKUP(B28,'RECOMMENDED PRICES'!$B$20:$F$58,5,0)*F28),0)} -> 55760000 | D28: {=C28/$C$80} -> 0.0056938601 | F28: {=VLOOKUP(B28,'Allocation OH and Target 2026'!$C$35:$K$91,9,0)} -> 68
B29: Jayanadi | C29: {=_xlfn.IFERROR((VLOOKUP(B29,'RECOMMENDED PRICES'!$B$20:$F$58,5,0)*F29),0)} -> 130285000 | D29: {=C29/$C$80} -> 0.013303884 | F29: {=VLOOKUP(B29,'Allocation OH and Target 2026'!$C$35:$K$91,9,0)} -> 71
B30: Sea Dragon | C30: {=_xlfn.IFERROR((VLOOKUP(B30,'RECOMMENDED PRICES'!$B$20:$F$76,5,0)*F30),0)} -> 55760000 | D30: {=C30/$C$80} -> 0.0056938601 | F30: {=VLOOKUP(B30,'Allocation OH and Target 2026'!$C$35:$K$91,9,0)} -> 68
B31: Sanjaya O4 | C31: {=_xlfn.IFERROR((VLOOKUP(B31,'RECOMMENDED PRICES'!$B$20:$F$76,5,0)*F31),0)} -> 379100000 | D31: {=C31/$C$80} -> 0.038711305 | F31: {=VLOOKUP(B31,'Allocation OH and Target 2026'!$C$35:$K$91,9,0)} -> 85
B32: Sanjaya O5 | C32: {=_xlfn.IFERROR((VLOOKUP(B32,'RECOMMENDED PRICES'!$B$20:$F$76,5,0)*F32),0)} -> 361260000 | D32: {=C32/$C$80} -> 0.036889596 | F32: {=VLOOKUP(B32,'Allocation OH and Target 2026'!$C$35:$K$91,9,0)} -> 81
B33: Almond Milk | C33: {=_xlfn.IFERROR((VLOOKUP(B33,'RECOMMENDED PRICES'!$B$20:$F$76,5,0)*F33),0)} -> 224640000 | D33: {=C33/$C$80} -> 0.022938822 | F33: {=VLOOKUP(B33,'Allocation OH and Target 2026'!$C$35:$K$91,9,0)} -> 54
B34: Honey Milk | C34: {=_xlfn.IFERROR((VLOOKUP(B34,'RECOMMENDED PRICES'!$B$20:$F$76,5,0)*F34),0)} -> 224640000 | D34: {=C34/$C$80} -> 0.022938822 | F34: {=VLOOKUP(B34,'Allocation OH and Target 2026'!$C$35:$K$91,9,0)} -> 54
B35: Eldorado 1 | C35: {=_xlfn.IFERROR((VLOOKUP(B35,'RECOMMENDED PRICES'!$B$20:$F$76,5,0)*F35),0)} -> 266240000 | D35: {=C35/$C$80} -> 0.027186752 | F35: {=VLOOKUP(B35,'Allocation OH and Target 2026'!$C$35:$K$91,9,0)} -> 64
B36: Eldorado 2 - Arya | C36: {=_xlfn.IFERROR((VLOOKUP(B36,'RECOMMENDED PRICES'!$B$20:$F$76,5,0)*F36),0)} -> 3.2794667e+08 | D36: {=C36/$C$80} -> 0.033487848 | F36: {=VLOOKUP(B36,'Allocation OH and Target 2026'!$C$35:$K$91,9,0)} -> 78.833333
B37: Eldorado 3 - Evgenii | C37: {=_xlfn.IFERROR((VLOOKUP(B37,'RECOMMENDED PRICES'!$B$20:$F$76,5,0)*F37),0)} -> 2.9813333e+08 | D37: {=C37/$C$80} -> 0.030443499 | F37: {=VLOOKUP(B37,'Allocation OH and Target 2026'!$C$35:$K$91,9,0)} -> 71.666667
B38: Eldorado 4 - Vadim | C38: {=_xlfn.IFERROR((VLOOKUP(B38,'RECOMMENDED PRICES'!$B$20:$F$76,5,0)*F38),0)} -> 252720000 | D38: {=C38/$C$80} -> 0.025806175 | F38: {=VLOOKUP(B38,'Allocation OH and Target 2026'!$C$35:$K$91,9,0)} -> 60.75
B39: Eldorado 5 - Robert | C39: {=_xlfn.IFERROR((VLOOKUP(B39,'RECOMMENDED PRICES'!$B$20:$F$76,5,0)*F39),0)} -> 299520000 | D39: {=C39/$C$80} -> 0.030585096 | F39: {=VLOOKUP(B39,'Allocation OH and Target 2026'!$C$35:$K$91,9,0)} -> 72
B40: Eldorado 6 - Vadim | C40: {=_xlfn.IFERROR((VLOOKUP(B40,'RECOMMENDED PRICES'!$B$20:$F$76,5,0)*F40),0)} -> 262080000 | D40: {=C40/$C$80} -> 0.026761959 | F40: {=VLOOKUP(B40,'Allocation OH and Target 2026'!$C$35:$K$91,9,0)} -> 63
B41: Boat Angels | C41: {=_xlfn.IFERROR((VLOOKUP(B41,'RECOMMENDED PRICES'!$B$20:$F$76,5,0)*F41),0)} -> 424320000 | D41: {=C41/$C$80} -> 0.043328886 | F41: {=VLOOKUP(B41,'Allocation OH and Target 2026'!$C$35:$K$91,9,0)} -> 102
... B79: Yacht T13 | C79: {=_xlfn.IFERROR((VLOOKUP(B79,'RECOMMENDED PRICES'!$B$20:$F$76,5,0)*F79),0)} -> 0 | D79: {=C79/$C$80} -> 0 | F79: {=VLOOKUP(B79,'Allocation OH and Target 2026'!$C$35:$K$91,9,0)} -> 3
B80: Private Boat Upgrade Total | C80: {=SUM(C26:C79)} -> 9793005000 | D80: {=C80/$C$80} -> 1
B82: Extra Pax (0-6) | C82: 0 | D82: {=C82/$C$93} | F82: 0
...

Sheet FCF 2025-2026 Forecast
F2: Actual | G2: Actual | H2: Actual | I2: Actual | J2: Forecast | K2: Forecast | L2: Forecast | M2: Forecast | N2: Forecast | O2: Forecast | P2: Forecast | Q2: Forecast | R2: Forecast | S2: Forecast | T2: Forecast | U2: Forecast | V2: Forecast | W2: Forecast | X2: Forecast | Y2: Forecast | Z2: Forecast | AA2: Forecast | AB2: Forecast | AC2: Forecast | AD2: Forecast | AE2: Forecast | AF2: Forecast | AG2: Forecast | AH2: Forecast | AI2: Forecast | AJ2: Forecast | AK2: Forecast
B3: in thousands IDR | F3: 45413 | G3: 45444 | H3: 45474 | I3: 45505 | J3: 45536 | K3: 45566 | L3: 45597 | M3: 45627 | N3: 45658 | O3: 45689 | P3: 45717 | Q3: 45748 | R3: 45778 | S3: 45809 | T3: 45839 | U3: 45870 | V3: 45901 | W3: 45931 | X3: 45962 | Y3: 45992 | Z3: 46023 | AA3: 46054 | AB3: 46082 | AC3: 46113 | AD3: 46143 | AE3: 46174 | AF3: 46204 | AG3: 46235 | AH3: 46266 | AI3: 46296 | AJ3: 46327 | AK3: 46357
B4: Cash flows from operating activities:
B5: Net Inflows:
D6: Forecasted Sales | E6: {=50896.35*16272} -> 8.2818541e+08 | F6: {='Monthly PnL 2024'!K9/1000} -> 5785086.4 | G6: {='Monthly PnL 2024'!J9/1000} -> 6950616.2 | H6: {='Monthly PnL 2024'!I9/1000} -> 9183590.2 | I6: {='Monthly PnL 2024'!H9/1000} -> 9559343.1 | J6: {='Monthly PnL 2024'!G9/1000} -> 8068004.5 | K6: {='Monthly PnL 2024'!F9/1000} -> 6866898.6 | L6: {='Monthly PnL 2024'!E9/1000} -> 5429922.4 | M6: {='Monthly PnL 2024'!D9/1000} -> 4324886.3 | N6: 4130380 | O6: 2791144.7 | P6: {=3366730.999} -> 3366731 | Q6: {=7865187} -> 7865187 | R6: {=6810201} -> 6810201 | S6: {=7770035} -> 7770035 | T6: {=8891109} -> 8891109 | U6: {=9354106-424609} -> 8929497 | V6: {=7368862-443025} -> 6925837 | W6: {=7520717} -> 7520717 | X6: {=4258506-364365-151086} -> 3743055 | Y6: {=4750134-324168-226403} -> 4199563 | Z6: {=3960365} -> 3960365 | AA6: {=Z6*(100%+'PnL 2025'!K4)} -> 2645311.1 | AB6: {=AA6*(100%+'PnL 2025'!J4)} -> 3476906.4 | AC6: {=AB6*(100%+'PnL 2025'!I4)} -> 8030663.9 | AD6: {=AC6*(100%+'PnL 2025'!H4)} -> 6767509.6 | AE6: {=AD6*(100%+'PnL 2025'!G4)} -> 7842118.7 | AF6: {=AE6*(100%+'PnL 2025'!F4)} -> 8998930.5 | AG6: {=AF6*(100%+'PnL 2025'!E4)} -> 9029046.3 | AH6: {=AG6*(100%+'PnL 2025'!D4)} -> 6832504.8 | AI6: {=AH6*(100%+'PnL 2025'!C4)} -> 7751033.9 | AJ6: {=AI6*(100%+'PnL 2025'!N4)} -> 5957428.3 | AK6: {=AJ6*(100%+'PnL 2025'!M4)} -> 5444709.1
D7: NPM | E7: {=50896.35*16272} -> 8.2818541e+08 | F7: {=F8/F6} -> 0.2489949 | G7: {=G8/G6} -> 0.20299923 | H7: {=H8/H6} -> 0.25131771 | I7: {=I8/I6} -> 0.25722042 | J7: {=J8/J6} -> 0.22273309 | K7: {=K8/K6} -> 0.16986774 | L7: {=L8/L6} -> 0.15270839 | M7: {=M8/M6} -> 0.030486992 | ... Z7: {=Z8/Z6} -> 0.18770416 | AA7: 0.1 | AB7: 0.1 | AC7: 0.2 | AD7: 0.2 | AE7: 0.2 | AF7: 0.2 | AG7: 0.2 | AH7: 0.2 | AI7: 0.15 | AJ7: 0.12 | AK7: 0.1
D8: Net Income | E8: {=50896.35*16272} -> 8.2818541e+08 | F8: {='Monthly PnL 2024'!K5/1000} -> 1440457 | G8: {='Monthly PnL 2024'!J5/1000} -> 1410969.7 | H8: {='Monthly PnL 2024'!I5/1000} -> 2307998.9 | I8: {='Monthly PnL 2024'!H5/1000} -> 2458858.3 | J8: {='Monthly PnL 2024'!G5/1000} -> 1797011.6 | K8: {='Monthly PnL 2024'!F5/1000} -> 1166464.5 | L8: {='Monthly PnL 2024'!E5/1000} -> 829194.7 | M8: {='Monthly PnL 2024'!D5/1000} -> 131852.77 | N8: 171158 | O8: -273381 | P8: {=-87674} -> -87674 | Q8: {=1887227} -> 1887227 | R8: {=1197493} -> 1197493 | S8: {=1389404} -> 1389404 | T8: {=1788491} -> 1788491 | U8: 1672235.6 | V8: {=880192} -> 880192 | W8: {=1723148} -> 1723148 | X8: -464482.74 | Y8: {=397438} -> 397438 | Z8: {=743377} -> 743377 | AA8: {=AA6*AA7} -> 264531.11 | AB8: {=AB6*AB7} -> 347690.64 | AC8: {=AC6*AC7} -> 1606132.8 | AD8: {=AD6*AD7} -> 1353501.9 | AE8: {=AE6*AE7} -> 1568423.7 | AF8: {=AF6*AF7} -> 1799786.1 | AG8: {=AG6*AG7} -> 1805809.3 | AH8: {=AH6*AH7} -> 1366501 | ... AK8: {=AK6*AK7} -> 544470.91
B9: Current month outflows: | E9: {=50896.35*16272} -> 8.2818541e+08
D10: Current Month Payroll | F10: 0 | G10: 0 | H10: 0 | I10: 0 | J10: 0 | K10: 0 | L10: 0 | M10: 0 | N10: 0 | O10: 0 | P10: 0 | Q10: 0 | R10: 0 | S10: 0 | T10: 0 | U10: 0 | V10: 0 | W10: 0 | X10: 0 | Y10: 0 | Z10: 0 | AA10: 0 | AB10: 0 | AC10: 0 | AD10: 0 | AE10: 0 | AF10: 0 | AG10: 0 | AH10: 0 | AI10: 0 | AJ10: 0 | AK10: 0
D11: LM Overhaul | E11: {=50896.35*16272} -> 8.2818541e+08 | F11: 0 | G11: 0 | H11: 0 | I11: 0 | J11: 0 | K11: 0 | L11: 0 | M11: 0 | N11: 0 | O11: 0 | P11: 0 | Q11: 0 | R11: 0 | S11: 0 | T11: 0 | U11: 0 | V11: 0 | W11: 0 | X11: 0 | Y11: 0 | Z11: 0 | AA11: 0 | AB11: 0 | AC11: 0 | AD11: 0 | AE11: 0 | AF11: 0 | AG11: 0 | AH11: 0 | AI11: 0 | AJ11: 0 | AK11: 0
D12: RJ Overhaul | F12: 0 | G12: 0 | H12: 0 | I12: 0 | J12: 0 | K12: 0 | L12: 0 | M12: 0 | N12: 0 | O12: 0 | P12: 0 | Q12: 0 | R12: 0 | S12: 0 | T12: 0 | U12: 0 | V12: 0 | W12: 0 | X12: 0 | Y12: 0 | Z12: 0 | AA12: 0 | AB12: -60000 | AC12: -120000 | AD12: 0 | AE12: 0 | AF12: 0 | AG12: 0 | AH12: 0 | AI12: 0 | AJ12: 0 | AK12: 0
D13: SH4 Overhaul | F13: 0 | G13: 0 | H13: 0 | I13: 0 | J13: 0 | K13: 0 | L13: 0 | M13: 0 | N13: 0 | O13: 0 | P13: 0 | Q13: 0 | R13: 0 | S13: 0 | T13: 0 | U13: 0 | V13: 0 | W13: 0 | X13: 0 | Y13: 0 | Z13: 0 | AA13: 0 | AB13: 0 | AC13: 0 | AD13: 0 | AE13: 0 | AF13: -124000 | AG13: 0 | AH13: 0 | AI13: 0 | AJ13: 0 | AK13: 0
D14: AM Overhaul | F14: 0 | G14: 0 | H14: 0 | I14: 0 | J14: 0 | K14: 0 | L14: 0 | M14: 0 | N14: 0 | O14: 0 | P14: 0 | Q14: 0 | R14: 0 | S14: 0 | T14: 0 | U14: 0 | V14: 0 | W14: 0 | X14: 0 | Y14: 0 | Z14: 0 | AA14: 0 | AB14: 0 | AC14: -84000 | AD14: 0 | AE14: 0 | AF14: 0 | AG14: 0 | AH14: 0 | AI14: 0 | AJ14: 0 | AK14: 0
D15: HM Overhaul | F15: 0 | G15: 0 | H15: 0 | I15: 0 | J15: 0 | K15: 0 | L15: 0 | M15: 0 | N15: 0 | O15: 0 | P15: 0 | Q15: 0 | R15: 0 | S15: 0 | T15: 0 | U15: 0 | V15: 0 | W15: 0 | X15: 0 | Y15: 0 | Z15: 0 | AA15: 0 | AB15: 0 | AC15: 0 | AD15: -84000 | AE15: 0 | AF15: 0 | AG15: 0 | AH15: 0 | AI15: 0 | AJ15: 0 | AK15: 0
D16: Unplanned expenses | E16: {=50896.35*16272} -> 8.2818541e+08 | F16: 0 | G16: 0 | H16: 0 | I16: 0 | J16: 0 | K16: 0 | L16: 0 | M16: 0 | N16: 0 | O16: 0 | P16: 0 | Q16: 0 | R16: 0 | S16: 0 | T16: 0 | U16: 0 | V16: 0 | W16: 0 | X16: 0 | Y16: 0 | Z16: 0 | AA16: 0 | AB16: 0 | AC16: 0 | AD16: 0 | AE16: 0 | AF16: 0 | AG16: 0 | AH16: 0 | AI16: 0 | AJ16: 0 | AK16: 0
E17: {=50896.35*16272} -> 8.2818541e+08
B18: Cash flows from investing activities: | E18: {=50896.35*16272} -> 8.2818541e+08
B19: Project Serangan: | E19: {=50896.35*16272} -> 8.2818541e+08
B20: Total project cost | D20: {=-SUM(F21:V25)+180000+959972+180000} -> 1319972
D21: Pergola payment #2 | E21: {=50896.35*16272} -> 8.2818541e+08 | F21: 0 | G21: 0 | H21: 0 | I21: 0 | J21: 0 | K21: 0 | L21: 0 | M21: 0 | N21: 0 | O21: 0 | P21: 0 | Q21: 0 | R21: 0 | S21: 0 | T21: 0 | U21: 0 | V21: 0 | W21: 0 | X21: 0 | Y21: 0 | Z21: 0 | AA21: 0 | AB21: 0 | AC21: 0 | AD21: 0 | AE21: 0 | AF21: 0 | AG21: 0 | AH21: 0 | AI21: 0 | AJ21: 0 | AK21: 0
D22: Plants and gardening | E22: {=50896.35*16272} -> 8.2818541e+08 | F22: 0 | G22: 0 | H22: 0 | I22: 0 | J22: 0 | K22: 0 | L22: 0 | M22: 0 | N22: 0 | O22: 0 | P22: 0 | Q22: 0 | R22: 0 | S22: 0 | T22: 0 | U22: 0 | V22: 0 | W22: 0 | X22: 0 | Y22: 0 | Z22: 0 | AA22: 0 | AB22: 0 | AC22: 0 | AD22: 0 | AE22: 0 | AF22: 0 | AG22: 0 | AH22: 0 | AI22: 0 | AJ22: 0 | AK22: 0
D23: Furniture and other equipment | E23: {=50896.35*16272} -> 8.2818541e+08 | F23: 0 | G23: 0 | H23: 0 | I23: 0 | J23: 0 | K23: 0 | L23: 0 | M23: 0 | N23: 0 | O23: 0 | P23: 0 | Q23: 0 | R23: 0 | S23: 0 | T23: 0 | U23: 0 | V23: 0 | W23: 0 | X23: 0 | Y23: 0 | Z23: 0 | AA23: 0 | AB23: 0 | AC23: 0 | AD23: 0 | AE23: 0 | AF23: 0 | AG23: 0 | AH23: 0 | AI23: 0 | AJ23: 0 | AK23: 0
D24: Construction and other Arif's payments | F24: 0 | G24: 0 | H24: 0 | I24: 0 | J24: 0 | K24: 0 | L24: 0 | M24: 0 | N24: 0 | O24: 0 | P24: 0 | Q24: 0 | R24: 0 | S24: 0 | T24: 0 | U24: 0 | V24: 0 | W24: 0 | X24: 0 | Y24: 0 | Z24: 0 | AA24: 0 | AB24: 0 | AC24: 0 | AD24: 0 | AE24: 0 | AF24: 0 | AG24: 0 | AH24: 0 | AI24: 0 | AJ24: 0 | AK24: 0
D25: Second rent payment | F25: 0 | G25: 0 | H25: 0 | I25: 0 | J25: 0 | K25: 0 | L25: 0 | M25: 0 | N25: 0 | O25: 0 | P25: 0 | Q25: 0 | R25: 0 | S25: 0 | T25: 0 | U25: 0 | V25: 0 | W25: 0 | X25: 0 | Y25: 0 | Z25: 0 | AA25: 0 | AB25: 0 | AC25: 0 | AD25: 0 | AE25: 0 | AF25: 0 | AG25: 0 | AH25: 0 | AI25: 0 | AJ25: 0 | AK25: 0
B27: Project Bali Boat Builders:
B28: Total project cost | D28: {=-SUM(F34:V54)} -> 0
D29: Advance from Arya | F29: 0 | G29: 0 | H29: 0 | I29: 0 | J29: 0 | K29: 0 | L29: 0 | M29: 0 | N29: 0 | O29: 0 | P29: 0 | Q29: 0 | R29: 0 | S29: 0 | T29: 0 | U29: 0 | V29: 0 | W29: 0 | X29: 0 | Y29: 0 | Z29: 0 | AA29: 0 | AB29: 110000 | AC29: 0 | AD29: 0 | AE29: 0 | AF29: 0 | AG29: 0 | AH29: 0 | AI29: 0 | AJ29: 0 | AK29: 0
D30: Advance from Eugene | F30: 0 | G30: 0 | H30: 0 | I30: 0 | J30: 0 | K30: 0 | L30: 0 | M30: 0 | N30: 0 | O30: 0 | P30: 0 | Q30: 0 | R30: 0 | S30: 0 | T30: 0 | U30: 0 | V30: 0 | W30: 0 | X30: 0 | Y30: 0 | Z30: 0 | AA30: 0 | AB30: 0 | AC30: 0 | AD30: 0 | AE30: 0 | AF30: 0 | AG30: 0 | AH30: 0 | AI30: 0 | AJ30: 0 | AK30: 0
D31: Advance from Vadim Boat 4 | F31: 0 | G31: 0 | H31: 0 | I31: 0 | J31: 0 | K31: 0 | L31: 0 | M31: 0 | N31: 0 | O31: 0 | P31: 0 | Q31: 0 | R31: 0 | S31: 0 | T31: 0 | U31: 0 | V31: 0 | W31: 0 | X31: 0 | Y31: 0 | Z31: 0 | AA31: {=2490000*30%} -> 747000 | AB31: 0 | AC31: {=2490000*40%} -> 996000 | AD31: 0 | AE31: 0 | AF31: 0 | AG31: 0 | AH31: 0 | AI31: 0 | AJ31: 0 | AK31: 0
D32: Advance from Robert Boat 5 | F32: 0 | G32: 0 | H32: 0 | I32: 0 | J32: 0 | K32: 0 | L32: 0 | M32: 0 | N32: 0 | O32: 0 | P32: 0 | Q32: 0 | R32: 0 | S32: 0 | T32: 0 | U32: 0 | V32: 0 | W32: 0 | X32: 0 | Y32: 0 | Z32: 0 | AA32: 0 | AB32: {=2770000*30%} -> 831000 | AC32: 0 | AD32: {=2770000*40%} -> 1108000 | AE32: 0 | AF32: 0 | AG32: 0 | AH32: 0 | AI32: 0 | AJ32: 0 | AK32: 0
D33: Advance from Osamah Boat 6 | F33: 0 | G33: 0 | H33: 0 | I33: 0 | J33: 0 | K33: 0 | L33: 0 | M33: 0 | N33: 0 | O33: 0 | P33: 0 | Q33: 0 | R33: 0 | S33: 0 | T33: 0 | U33: 0 | V33: 0 | W33: 0 | X33: 0 | Y33: 0 | Z33: 0 | AA33: 917000 | AB33: 0 | AC33: {=2936000*30%} -> 880800 | AD33: 0 | AE33: {=2936000*40%} -> 1174400 | AF33: 0 | AG33: 0 | AH33: 0 | AI33: 0 | AJ33: 0 | AK33: 0
D34: Loan to PT Fortune Yachts Bali | F34: 0 | G34: 0 | H34: 0 | I34: 0 | J34: 0 | K34: 0 | L34: 0 | M34: 0 | N34: 0 | O34: 0 | P34: 0 | Q34: 0 | R34: 0 | T34: 0 | U34: 0 | V34: 0 | W34: 0 | X34: 0 | Y34: 0 | Z34: 0 | AA34: -140000 | AB34: -140000 | AC34: -140000 | AD34: 0 | AE34: 0 | AF34: 0 | AG34: 0 | AH34: 0 | AI34: 0 | AJ34: 0 | AK34: 0
D35: Order Boat 1 | F35: 0 | G35: 0 | H35: 0 | I35: 0 | J35: 0 | K35: 0 | L35: 0 | M35: 0 | N35: 0 | O35: 0 | P35: 0 | Q35: 0 | R35: 0 | S35: 0 | T35: 0 | U35: 0 | V35: 0 | W35: 0 | X35: 0 | Y35: 0 | Z35: 0 | AA35: {=-453600+120000+70000+50000+50000+50000+50000+50000} -> -13600 | AB35: 0 | AC35: 0 | AD35: 0 | AE35: 0 | AF35: 0 | AG35: 0 | AH35: 0 | AI35: 0 | AJ35: 0 | AK35: 0
D36: Order Boat 2 | F36: 0 | G36: 0 | H36: 0 | I36: 0 | J36: 0 | K36: 0 | L36: 0 | M36: 0 | N36: 0 | O36: 0 | P36: 0 | Q36: 0 | R36: 0 | T36: 0 | U36: 0 | V36: 0 | W36: 0 | X36: 0 | Y36: 0 | Z36: 0 | AA36: {=-453600+50000+50000+50000+50000+50000+50000+50000+20000+20000+20000+10000+10000} -> -23600 | AB36: 0 | AC36: 0 | AD36: 0 | AE36: 0 | AF36: 0 | AG36: 0 | AH36: 0 | AI36: 0 | AJ36: 0 | AK36: 0
D37: Order Boat 3 | F37: 0 | G37: 0 | H37: 0 | I37: 0 | J37: 0 | K37: 0 | L37: 0 | M37: 0 | N37: 0 | O37: 0 | P37: 0 | Q37: 0 | R37: 0 | S37: 0 | T37: 0 | U37: 0 | V37: 0 | W37: 0 | X37: 0 | Y37: 0 | Z37: 0 | AA37: {=-453600+40000+50000+100000+50000+30000+30000+30000+20000+30000+20000+20000} -> -33600 | AB37: 0 | AC37: 0 | AD37: 0 | AE37: 0 | AF37: 0 | AG37: 0 | AH37: 0 | AI37: 0 | AJ37: 0 | AK37: 0
D38: Order Boat 4 | F38: 0 | G38: 0 | H38: 0 | I38: 0 | J38: 0 | K38: 0 | L38: 0 | M38: 0 | N38: 0 | O38: 0 | P38: 0 | Q38: 0 | R38: 0 | S38: 0 | T38: 0 | U38: 0 | V38: 0 | W38: 0 | X38: 0 | Y38: 0 | Z38: 0 | AA38: {=-453600+100000+50000+50000+50000+50000+20000} -> -133600 | AB38: 0 | AC38: 0 | AD38: 0 | AE38: 0 | AF38: 0 | AG38: 0 | AH38: 0 | AI38: 0 | AJ38: 0 | AK38: 0
D39: Order Boat 5 | F39: 0 | G39: 0 | H39: 0 | I39: 0 | J39: 0 | K39: 0 | L39: 0 | M39: 0 | N39: 0 | O39: 0 | P39: 0 | Q39: 0 | R39: 0 | S39: 0 | T39: 0 | U39: 0 | V39: 0 | W39: 0 | X39: 0 | Y39: 0 | Z39: 0 | AA39: {=-453600+200000+50000+20000} -> -183600 | AB39: 0 | AC39: 0 | AD39: 0 | AE39: 0 | AF39: 0 | AG39: 0 | AH39: 0 | AI39: 0 | AJ39: 0 | AK39: 0
D40: Order Boat 6 | F40: 0 | G40: 0 | H40: 0 | I40: 0 | J40: 0 | K40: 0 | L40: 0 | M40: 0 | N40: 0 | O40: 0 | P40: 0 | Q40: 0 | R40: 0 | S40: 0 | T40: 0 | U40: 0 | V40: 0 | W40: 0 | X40: 0 | Y40: 0 | Z40: 0 | AA40: -453600 | AB40: 0 | AC40: 0 | AD40: 0 | AE40: 0 | AF40: 0 | AG40: 0 | AH40: 0 | AI40: 0 | AJ40: 0 | AK40: 0
D41: Order Boat 7 | F41: 0 | G41: 0 | H41: 0 | I41: 0 | J41: 0 | K41: 0 | L41: 0 | M41: 0 | N41: 0 | O41: 0 | P41: 0 | Q41: 0 | R41: 0 | S41: 0 | T41: 0 | U41: 0 | V41: 0 | W41: 0 | X41: 0 | Y41: 0 | Z41: 0 | AA41: 0 | AB41: 0 | AC41: 0 | AD41: -453600 | AE41: 0 | AF41: 0 | AG41: 0 | AH41: 0 | AI41: 0 | AJ41: 0 | AK41: 0
D42: Order Boat 8 | F42: 0 | G42: 0 | H42: 0 | I42: 0 | J42: 0 | K42: 0 | L42: 0 | M42: 0 | N42: 0 | O42: 0 | P42: 0 | Q42: 0 | R42: 0 | S42: 0 | T42: 0 | U42: 0 | V42: 0 | W42: 0 | X42: 0 | Y42: 0 | Z42: 0 | AA42: 0 | AB42: 0 | AC42: 0 | AD42: 0 | AE42: -453600 | AF42: 0 | AG42: 0 | AH42: 0 | AI42: 0 | AJ42: 0 | AK42: 0
...

Sheet Private Boats 2026 Target
A2: 1 | B2: Boat: | C2: SWEETHEART 4 | AE2: Average direct cost | AF2: {=AVERAGE(Q5:Q10)} -> 6984733.3 | AG2: Extra pax cost | AH2: {=AVERAGE(Q11:Q18)-AF2} -> 2103062.5 | AI2: Average profit margin | AJ2: {=AVERAGE(Y5:Y12)} -> 2879936.5 | AK2: Average total cost | AL2: {=AVERAGE(W5:W10)} -> 11219309 | AM2: 1-Pax cost | AN2: {=W5} -> 10741809
C3: DIRECT COSTS | S3: INDIRECT COST | W3: TARGER PRICING | AC3: Წ
B4: Guests u | C4: Boat Rent u | D4: Guides | E4: Guides Salary & Tax | F4: Towels | G4: Ice & Water | H4: NP + Bali Clearance + Parking | I4: Seran Retribution | J4: Seran Parking and Mooring | K4: Offering | L4: Fruits | M4: Lunch | N4: Fuel Pertamax | O4: Crew Salary & Tax u | P4: Boat Tax | Q4: TOTAL DIRECT | S4: Indirect and Admin Cost per tour | T4: 3D (Depretiation, Docking, Doc) fees per tour u | U4: TOTAL INDIRECT | W4: TOTAL COST | X4: Tax Markup 0.5% | Y4: Targer Net Profit Margin 25% | Z4: TARGET PRICE PER TOUR | AA4: Extra Pax Charge | AC4: RECOMMENED BASE PRICE PER TOUR
B5: 1 | C5: {=IF(B5>0,IF(VLOOKUP(C2,'Boats Data Sheet 2026'!$C$3:$J$57,8,0)="N/A",0,VLOOKUP(C2,'Boats Data Sheet 2026'!$C$3:$J$57,8,0)),"N/A")} -> 0 | D5: {=IF(B5>7,2,IF(B5=0,"N/A",1))} -> 1 | E5: {=_xlfn.IFERROR(SUM('Direct Costs 2026'!$C$4:$C$5)*D5,"N/A")} -> 875500 | F5: {=_xlfn.IFERROR('Direct Costs 2026'!$C$43*B5,"N/A")} -> 6000 | G5: {=IF(B5>0,'Direct Costs 2026'!$C$25,"N/A")} -> 90000 | H5: {=IF(B5>0,('Direct Costs 2026'!$C$15+'Direct Costs 2026'!$C$17+'Direct Costs 2026'!$C$14),"N/A")} -> 580000 | I5: {=IF(B5>0,'Direct Costs 2026'!$C$19+'Direct Costs 2026'!$C$18*B5,"N/A")} -> 110000 | J5: {=IF(B5>0,SUM('Direct Costs 2026'!$C$20:$C$21),"N/A")} -> 98333.333 | K5: {=IF(B5>0,'Direct Costs 2026'!$C$26,"N/A")} -> 20000 | L5: {=IF(B5>0,'Direct Costs 2026'!$C$23,"N/A")} -> 140000 | M5: {=IF(B5>0,'Direct Costs 2026'!$C$45*B5,"N/A")} -> 150000 | N5: {=IF(B5>0,_xlfn.IFERROR(VLOOKUP(C2,'Boats Data Sheet 2026'!$C$3:$I$57,7,0)*'Direct Costs 2026'!$C$36,"N/A"),"N/A")} -> 3325000 | O5: {=IF(B5>0,IF(OR(VLOOKUP(C2,'Boats Data Sheet 2026'!$C$3:$F$57,4,0)="Own",VLOOKUP(C2,'Boats Data Sheet 2026'!$C$3:$F$57,4,0)="Management"),('Direct Costs 2026'!$C$37+'Direct Costs 2026'!$C$39),"N/A"),"N/A")} -> 1112400 | P5: {=_xlfn.IFERROR('Direct Costs 2026'!$C$27*C5,"N/A")} -> 0 | Q5: {=_xlfn.IFERROR(C5+SUM(E5:P5),"N/A")} -> 6507233.3 | S5: {=IF(B5>0,'Allocation OH and Target 2026'!$E$31,"N/A")} -> 3100447.2 | T5: {=IF(B5>0,VLOOKUP(C2,'Allocation OH and Target 2026'!$C$35:$S$87,17,0),"N/A")} -> 1134128.1 | U5: {=_xlfn.IFERROR((S5+T5),"N/A")} -> 4234575.3 | W5: {=_xlfn.IFERROR(U5+Q5,"N/A")} -> 10741809 | X5: {=_xlfn.IFERROR(W5*0.5%,"N/A")} -> 53709.043 | Y5: {=_xlfn.IFERROR(W5*25%,"N/A")} -> 2685452.2 | Z5: {=IF(B5>0,SUM(W5:Y5),"N/A")} -> 13480970 | AA5: 0 | AC5: {=IF(B5=6,Z5,"N/A")} -> N/A
B6: {=IF(B5=0,0,IF(B5<VLOOKUP(C2,'Boats Data Sheet 2026'!$C$3:$H$57,6,0),B5+1,0))} -> 2 | C6: {=IF(B6>0,IF(VLOOKUP(C2,'Boats Data Sheet 2026'!$C$3:$J$57,8,0)="N/A",0,VLOOKUP(C2,'Boats Data Sheet 2026'!$C$3:$J$57,8,0)),"N/A")} -> 0 | D6: {=IF(B6>7,2,IF(B6=0,"N/A",1))} -> 1 | E6: {=_xlfn.IFERROR(SUM('Direct Costs 2026'!$C$4:$C$5)*D6,"N/A")} -> 875500 | F6: {=_xlfn.IFERROR('Direct Costs 2026'!$C$43*B6,"N/A")} -> 12000 | G6: {=IF(B6>0,'Direct Costs 2026'!$C$25,"N/A")} -> 90000 | H6: {=IF(B6>0,('Direct Costs 2026'!$C$15+'Direct Costs 2026'!$C$17+'Direct Costs 2026'!$C$14),"N/A")} -> 580000 | I6: {=IF(B6>0,'Direct Costs 2026'!$C$19+'Direct Costs 2026'!$C$18*B6,"N/A")} -> 145000 | J6: {=IF(B6>0,SUM('Direct Costs 2026'!$C$20:$C$21),"N/A")} -> 98333.333 | K6: {=IF(B6>0,'Direct Costs 2026'!$C$26,"N/A")} -> 20000 | L6: {=IF(B6>0,'Direct Costs 2026'!$C$23,"N/A")} -> 140000 | M6: {=IF(B6>0,'Direct Costs 2026'!$C$45*B6,"N/A")} -> 300000 | N6: {=IF(B6>0,_xlfn.IFERROR(VLOOKUP(C2,'Boats Data Sheet 2026'!$C$3:$I$57,7,0)*'Direct Costs 2026'!$C$36,"N/A"),"N/A")} -> 3325000 | O6: {=IF(B6>0,IF(OR(VLOOKUP(C2,'Boats Data Sheet 2026'!$C$3:$F$57,4,0)="Own",VLOOKUP(C2,'Boats Data Sheet 2026'!$C$3:$F$57,4,0)="Management"),('Direct Costs 2026'!$C$37+'Direct Costs 2026'!$C$39),"N/A"),"N/A")} -> 1112400 | P6: {=_xlfn.IFERROR('Direct Costs 2026'!$C$27*C6,"N/A")} -> 0 | Q6: {=_xlfn.IFERROR(C6+SUM(E6:P6),"N/A")} -> 6698233.3 | S6: {=IF(B6>0,'Allocation OH and Target 2026'!$E$31,"N/A")} -> 3100447.2 | T6: {=IF(B6>0,VLOOKUP(C2,'Allocation OH and Target 2026'!$C$35:$S$87,17,0),"N/A")} -> 1134128.1 | U6: {=_xlfn.IFERROR((S6+T6),"N/A")} -> 4234575.3 | W6: {=_xlfn.IFERROR(U6+Q6,"N/A")} -> 10932809 | X6: {=_xlfn.IFERROR(W6*0.5%,"N/A")} -> 54664.043 | Y6: {=_xlfn.IFERROR(W6*25%,"N/A")} -> 2733202.2 | Z6: {=IF(B6>0,SUM(W6:Y6),"N/A")} -> 13720675 | AA6: {=_xlfn.IFERROR((Z6-Z5),"N/A")} -> 239705 | AC6: {=IF(B6=6,AVERAGE(Z6),"N/A")} -> N/A
B7: {=IF(B6=0,0,IF(B6<VLOOKUP(C2,'Boats Data Sheet 2026'!$C$3:$H$57,6,0),B6+1,0))} -> 3 | C7: {=IF(B7>0,IF(VLOOKUP(C2,'Boats Data Sheet 2026'!$C$3:$J$57,8,0)="N/A",0,VLOOKUP(C2,'Boats Data Sheet 2026'!$C$3:$J$57,8,0)),"N/A")} -> 0 | D7: {=IF(B7>7,2,IF(B7=0,"N/A",1))} -> 1 | E7: {=_xlfn.IFERROR(SUM('Direct Costs 2026'!$C$4:$C$5)*D7,"N/A")} -> 875500 | F7: {=_xlfn.IFERROR('Direct Costs 2026'!$C$43*B7,"N/A")} -> 18000 | G7: {=IF(B7>0,'Direct Costs 2026'!$C$25,"N/A")} -> 90000 | H7: {=IF(B7>0,('Direct Costs 2026'!$C$15+'Direct Costs 2026'!$C$17+'Direct Costs 2026'!$C$14),"N/A")} -> 580000 | I7: {=IF(B7>0,'Direct Costs 2026'!$C$19+'Direct Costs 2026'!$C$18*B7,"N/A")} -> 180000 | J7: {=IF(B7>0,SUM('Direct Costs 2026'!$C$20:$C$21),"N/A")} -> 98333.333 | K7: {=IF(B7>0,'Direct Costs 2026'!$C$26,"N/A")} -> 20000 | L7: {=IF(B7>0,'Direct Costs 2026'!$C$23,"N/A")} -> 140000 | M7: {=IF(B7>0,'Direct Costs 2026'!$C$45*B7,"N/A")} -> 450000 | N7: {=IF(B7>0,_xlfn.IFERROR(VLOOKUP(C2,'Boats Data Sheet 2026'!$C$3:$I$57,7,0)*'Direct Costs 2026'!$C$36,"N/A"),"N/A")} -> 3325000 | O7: {=IF(B7>0,IF(OR(VLOOKUP(C2,'Boats Data Sheet 2026'!$C$3:$F$57,4,0)="Own",VLOOKUP(C2,'Boats Data Sheet 2026'!$C$3:$F$57,4,0)="Management"),('Direct Costs 2026'!$C$37+'Direct Costs 2026'!$C$39),"N/A"),"N/A")} -> 1112400 | P7: {=_xlfn.IFERROR('Direct Costs 2026'!$C$27*C7,"N/A")} -> 0 | Q7: {=_xlfn.IFERROR(C7+SUM(E7:P7),"N/A")} -> 6889233.3 | S7: {=IF(B7>0,'Allocation OH and Target 2026'!$E$31,"N/A")} -> 3100447.2 | T7: {=IF(B7>0,VLOOKUP(C2,'Allocation OH and Target 2026'!$C$35:$S$87,17,0),"N/A")} -> 1134128.1 | U7: {=_xlfn.IFERROR((S7+T7),"N/A")} -> 4234575.3 | W7: {=_xlfn.IFERROR(U7+Q7,"N/A")} -> 11123809 | X7: {=_xlfn.IFERROR(W7*0.5%,"N/A")} -> 55619.043 | Y7: {=_xlfn.IFERROR(W7*25%,"N/A")} -> 2780952.2 | Z7: {=IF(B7>0,SUM(W7:Y7),"N/A")} -> 13960380 | AA7: {=_xlfn.IFERROR((Z7-Z6),"N/A")} -> 239705 | AC7: {=IF(B7=6,AVERAGE(Z7),"N/A")} -> N/A
B8: {=IF(B7=0,0,IF(B7<VLOOKUP(C2,'Boats Data Sheet 2026'!$C$3:$H$57,6,0),B7+1,0))} -> 4 | C8: {=IF(B8>0,IF(VLOOKUP(C2,'Boats Data Sheet 2026'!$C$3:$J$57,8,0)="N/A",0,VLOOKUP(C2,'Boats Data Sheet 2026'!$C$3:$J$57,8,0)),"N/A")} -> 0 | D8: {=IF(B8>7,2,IF(B8=0,"N/A",1))} -> 1 | E8: {=_xlfn.IFERROR(SUM('Direct Costs 2026'!$C$4:$C$5)*D8,"N/A")} -> 875500 | F8: {=_xlfn.IFERROR('Direct Costs 2026'!$C$43*B8,"N/A")} -> 24000 | G8: {=IF(B8>0,'Direct Costs 2026'!$C$25,"N/A")} -> 90000 | H8: {=IF(B8>0,('Direct Costs 2026'!$C$15+'Direct Costs 2026'!$C$17+'Direct Costs 2026'!$C$14),"N/A")} -> 580000 | I8: {=IF(B8>0,'Direct Costs 2026'!$C$19+'Direct Costs 2026'!$C$18*B8,"N/A")} -> 215000 | J8: {=IF(B8>0,SUM('Direct Costs 2026'!$C$20:$C$21),"N/A")} -> 98333.333 | K8: {=IF(B8>0,'Direct Costs 2026'!$C$26,"N/A")} -> 20000 | L8: {=IF(B8>0,'Direct Costs 2026'!$C$23,"N/A")} -> 140000 | M8: {=IF(B8>0,'Direct Costs 2026'!$C$45*B8,"N/A")} -> 600000 | N8: {=IF(B8>0,_xlfn.IFERROR(VLOOKUP(C2,'Boats Data Sheet 2026'!$C$3:$I$57,7,0)*'Direct Costs 2026'!$C$36,"N/A"),"N/A")} -> 3325000 | O8: {=IF(B8>0,IF(OR(VLOOKUP(C2,'Boats Data Sheet 2026'!$C$3:$F$57,4,0)="Own",VLOOKUP(C2,'Boats Data Sheet 2026'!$C$3:$F$57,4,0)="Management"),('Direct Costs 2026'!$C$37+'Direct Costs 2026'!$C$39),"N/A"),"N/A")} -> 1112400 | P8: {=_xlfn.IFERROR('Direct Costs 2026'!$C$27*C8,"N/A")} -> 0 | Q8: {=_xlfn.IFERROR(C8+SUM(E8:P8),"N/A")} -> 7080233.3 | S8: {=IF(B8>0,'Allocation OH and Target 2026'!$E$31,"N/A")} -> 3100447.2 | T8: {=IF(B8>0,VLOOKUP(C2,'Allocation OH and Target 2026'!$C$35:$S$87,17,0),"N/A")} -> 1134128.1 | U8: {=_xlfn.IFERROR((S8+T8),"N/A")} -> 4234575.3 | W8: {=_xlfn.IFERROR(U8+Q8,"N/A")} -> 11314809 | X8: {=_xlfn.IFERROR(W8*0.5%,"N/A")} -> 56574.043 | Y8: {=_xlfn.IFERROR(W8*25%,"N/A")} -> 2828702.2 | Z8: {=IF(B8>0,SUM(W8:Y8),"N/A")} -> 14200085 | AA8: {=_xlfn.IFERROR((Z8-Z7),"N/A")} -> 239705 | AC8: {=IF(B8=6,AVERAGE(Z8),"N/A")} -> N/A
B9: {=IF(B8=0,0,IF(B8<VLOOKUP(C2,'Boats Data Sheet 2026'!$C$3:$H$57,6,0),B8+1,0))} -> 5 | C9: {=IF(B9>0,IF(VLOOKUP(C2,'Boats Data Sheet 2026'!$C$3:$J$57,8,0)="N/A",0,VLOOKUP(C2,'Boats Data Sheet 2026'!$C$3:$J$57,8,0)),"N/A")} -> 0 | D9: {=IF(B9>7,2,IF(B9=0,"N/A",1))} -> 1 | E9: {=_xlfn.IFERROR(SUM('Direct Costs 2026'!$C$4:$C$5)*D9,"N/A")} -> 875500 | F9: {=_xlfn.IFERROR('Direct Costs 2026'!$C$43*B9,"N/A")} -> 30000 | G9: {=IF(B9>0,'Direct Costs 2026'!$C$25,"N/A")} -> 90000 | H9: {=IF(B9>0,('Direct Costs 2026'!$C$15+'Direct Costs 2026'!$C$17+'Direct Costs 2026'!$C$14),"N/A")} -> 580000 | I9: {=IF(B9>0,'Direct Costs 2026'!$C$19+'Direct Costs 2026'!$C$18*B9,"N/A")} -> 250000 | J9: {=IF(B9>0,SUM('Direct Costs 2026'!$C$20:$C$21),"N/A")} -> 98333.333 | K9: {=IF(B9>0,'Direct Costs 2026'!$C$26,"N/A")} -> 20000 | L9: {=IF(B9>0,'Direct Costs 2026'!$C$23,"N/A")} -> 140000 | M9: {=IF(B9>0,'Direct Costs 2026'!$C$45*B9,"N/A")} -> 750000 | N9: {=IF(B9>0,_xlfn.IFERROR(VLOOKUP(C2,'Boats Data Sheet 2026'!$C$3:$I$57,7,0)*'Direct Costs 2026'!$C$36,"N/A"),"N/A")} -> 3325000 | O9: {=IF(B9>0,IF(OR(VLOOKUP(C2,'Boats Data Sheet 2026'!$C$3:$F$57,4,0)="Own",VLOOKUP(C2,'Boats Data Sheet 2026'!$C$3:$F$57,4,0)="Management"),('Direct Costs 2026'!$C$37+'Direct Costs 2026'!$C$39),"N/A"),"N/A")} -> 1112400 | P9: {=_xlfn.IFERROR('Direct Costs 2026'!$C$27*C9,"N/A")} -> 0 | Q9: {=_xlfn.IFERROR(C9+SUM(E9:P9),"N/A")} -> 7271233.3 | S9: {=IF(B9>0,'Allocation OH and Target 2026'!$E$31,"N/A")} -> 3100447.2 | T9: {=IF(B9>0,VLOOKUP(C2,'Allocation OH and Target 2026'!$C$35:$S$87,17,0),"N/A")} -> 1134128.1 | U9: {=_xlfn.IFERROR((S9+T9),"N/A")} -> 4234575.3 | W9: {=_xlfn.IFERROR(U9+Q9,"N/A")} -> 11505809 | X9: {=_xlfn.IFERROR(W9*0.5%,"N/A")} -> 57529.043 | Y9: {=_xlfn.IFERROR(W9*25%,"N/A")} -> 2876452.2 | Z9: {=IF(B9>0,SUM(W9:Y9),"N/A")} -> 14439790 | AA9: {=_xlfn.IFERROR((Z9-Z8),"N/A")} -> 239705 | AC9: {=IF(B9=6,AVERAGE(Z9),"N/A")} -> N/A
B10: {=IF(B9=0,0,IF(B9<VLOOKUP(C2,'Boats Data Sheet 2026'!$C$3:$H$57,6,0),B9+1,0))} -> 6 | C10: {=IF(B10>0,IF(VLOOKUP(C2,'Boats Data Sheet 2026'!$C$3:$J$57,8,0)="N/A",0,VLOOKUP(C2,'Boats Data Sheet 2026'!$C$3:$J$57,8,0)),"N/A")} -> 0 | D10: {=IF(B10>7,2,IF(B10=0,"N/A",1))} -> 1 | E10: {=_xlfn.IFERROR(SUM('Direct Costs 2026'!$C$4:$C$5)*D10,"N/A")} -> 875500 | F10: {=_xlfn.IFERROR('Direct Costs 2026'!$C$43*B10,"N/A")} -> 36000 | G10: {=IF(B10>0,'Direct Costs 2026'!$C$25,"N/A")} -> 90000 | H10: {=IF(B10>0,('Direct Costs 2026'!$C$15+'Direct Costs 2026'!$C$17+'Direct Costs 2026'!$C$14),"N/A")} -> 580000 | I10: {=IF(B10>0,'Direct Costs 2026'!$C$19+'Direct Costs 2026'!$C$18*B10,"N/A")} -> 285000 | J10: {=IF(B10>0,SUM('Direct Costs 2026'!$C$20:$C$21),"N/A")} -> 98333.333 | K10: {=IF(B10>0,'Direct Costs 2026'!$C$26,"N/A")} -> 20000 | L10: {=IF(B10>0,'Direct Costs 2026'!$C$23,"N/A")} -> 140000 | M10: {=IF(B10>0,'Direct Costs 2026'!$C$45*B10,"N/A")} -> 900000 | N10: {=IF(B10>0,_xlfn.IFERROR(VLOOKUP(C2,'Boats Data Sheet 2026'!$C$3:$I$57,7,0)*'Direct Costs 2026'!$C$36,"N/A"),"N/A")} -> 3325000 | O10: {=IF(B10>0,IF(OR(VLOOKUP(C2,'Boats Data Sheet 2026'!$C$3:$F$57,4,0)="Own",VLOOKUP(C2,'Boats Data Sheet 2026'!$C$3:$F$57,4,0)="Management"),('Direct Costs 2026'!$C$37+'Direct Costs 2026'!$C$39),"N/A"),"N/A")} -> 1112400 | P10: {=_xlfn.IFERROR('Direct Costs 2026'!$C$27*C10,"N/A")} -> 0 | Q10: {=_xlfn.IFERROR(C10+SUM(E10:P10),"N/A")} -> 7462233.3 | S10: {=IF(B10>0,'Allocation OH and Target 2026'!$E$31,"N/A")} -> 3100447.2 | T10: {=IF(B10>0,VLOOKUP(C2,'Allocation OH and Target 2026'!$C$35:$S$87,17,0),"N/A")} -> 1134128.1 | U10: {=_xlfn.IFERROR((S10+T10),"N/A")} -> 4234575.3 | W10: {=_xlfn.IFERROR(U10+Q10,"N/A")} -> 11696809 | X10: {=_xlfn.IFERROR(W10*0.5%,"N/A")} -> 58484.043 | Y10: {=_xlfn.IFERROR(W10*25%,"N/A")} -> 2924202.2 | Z10: {=IF(B10>0,SUM(W10:Y10),"N/A")} -> 14679495 | AA10: {=_xlfn.IFERROR((Z10-Z9),"N/A")} -> 239705 | AC10: {=IF(B10=6,AVERAGE(Z5:Z10),"N/A")} -> 14080232
